Workbook

Sheet DATA DE CONTROLES Y LLAVES
Q1: a la venta
G2: CENSO | K2: bloqueado disleidy diaz | L2: 84B | Q2: 221B | R2: 222B
G3: BLOQUES 27 AL 32
O4: Alejandro Tecnico | P4: 1B
B5: BLOQ. | C5: ESC. | D5: PISOS | E5: APTO. | F5: NOMBRES | G5: APELLIDOS | H5: ESTADO DE CONTROLES | I5: N° DE CONTROL | J5: N° LLAVE PEATONAL | K5: ref. de pago
B6: 27 | C6: 1 | D6: PB | E6: 1 | F6: FERNANDO | G6: DOS REY | H6: ACTIVO | I6: 26A | J6: 99 | K6: 5 $ + 40bs | O6: CODIFICACION DE LLAVES
F7: DEYSY | G7: DOS REY | J7: 100
F8: CHITO | G8: DOS REY | O8: CODIFICADAS | P8: EXONERADAS | Q8: PENDIENTES | R8: NUEVAS | S8: TOTAL | T8: GASTOS [$] | U8: RECAUDADO [$]
F9: DAYANA | G9: DOS REY | O9: 225 | P9: 30 | Q9: 0 | R9: 7 | S9: =O9-P9-Q9-R9 -> 188 | T9: 28.6 | U9: =(S9*3)-T9 -> 535.4 | X9: =38.67*3 -> 116.01
X10: =115-116.01 -> -1.01
D12: PB | E12: 3 | F12: ROSARIO | G12: ACOSTA | H12: ACTIVO | I12: 199A | J12: 166/167 | K12: 5 | U12: =U9-501 -> 34.4 | W12: =U9-S9 -> 347.4
F13: RODLANIER | G13: PAMELÁ | U13: =U12*38.67 -> 1330.248
U14: =U13-747.92 -> 582.328
B15: 27 | C15: 1 | D15: 1 | E15: 101 | F15: LIGIA (DE) | G15: ISTURIZ
D17: 1 | E17: 102 | F17: FLOR | G17: HERNÁNDEZ
F18: MARIO | G18: HERNÁNDEZ | H18: BLOQUEADO | I18: 53B
D20: 1 | E20: 104 | F20: ARTURO | G20: BORRERO | H20: ACTIVO | I20: 35A | J20: 204 / 205 | K20: 18153 | O20: CODIFICACION DE LLAVES
F21: Arturo | G21: Borrero | J21: 411/412/413/414 | K21: pendiente
O22: CODIFICADAS | P22: EXONERADAS | Q22: PENDIENTES | R22: NUEVAS | S22: TOTAL | T22: GASTOS [$] | U22: RECAUDADO [$]
O23: =309-225 -> 84 | P23: 4 | Q23: 3 | R23: 1 | S23: =O23-P23-Q23-R23 -> 76 | T23: 0 | U23: =(S23*3)-T23 -> 228
B25: 27 | C25: 1 | D25: 2 | E25: 201 | F25: MAYDE | G25: MADURO | H25: ACTIVO | I25: 245A | J25: 144 | K25: exonerada
F26: MERCEDES | G26: MADURO | J26: 141 | K26: exonerada | U26: =U23-180 -> 48
F27: CARLOS | G27: MADURO | J27: 145 | K27: exonerada | U27: =U26*39 -> 1872
F28: TOMÁS | G28: MADURO | J28: 90 | K28: 7122 | O28: llave 181 señor Jesús plomero | P28: cancelo 3$ | U28: =U27-700 -> 1172 | W28: =115*3 -> 345 | X28: =863-345 -> 518
F29: ARTURO | G29: MADURO | H29: ACTIVO | I29: 244A | J29: 142 | K29: exonerada | U29: =U28-518 -> 654
F30: ARTURO | G30: MADURO | H30: ACTIVO | I30: 58B
F31: IAN | G31: CHIVICO | J31: 143 | K31: exonerada
B33: 27 | C33: 1 | D33: 2 | E33: 202 | F33: CARLOS | G33: MORALES | H33: ACTIVO | I33: 216A | J33: 277 | K33: pago cuenta porton
F34: GLADYS | G34: BICHOF
F35: IDOSELVA | G35: MORALES | H35: ACTIVO | I35: 83B | J35: 276 | K35: pago a cuenta del portón
D37: 2 | E37: 204 | F37: AMARILIS | G37: GUTIÉRREZ | H37: ACTIVO | I37: 96A
F38: ANAIBEL | G38: GUTIÉRREZ
G39: GUTIÉRREZ
B41: 27 | C41: 1 | D41: 3 | E41: 301 | F41: NOHEMÍ | G41: HERNÁNDEZ | H41: ACTIVO | I41: 43A | J41: 22 | K41: 2$+ 39Bs
F42: NOHEMÍ | G42: HERNÁNDEZ (HIJA) | H42: SUSPENDIDO | I42: 44A
D44: 3 | E44: 302 | F44: NELSON | G44: ISTURIZ | H44: BLOQUEADO | I44: 225A
F45: NELSON | G45: ISTURIZ (HIJO) | H45: BLOQUEADO | I45: 226A
F46: GUILLERMO | G46: ISTURIZ
D48: 3 | E48: 304 | F48: MARY | G48: ELÍSEO | H48: ACTIVO | I48: 126A
F49: MIREYA | G49: ELÍSEO | J49: 20 | K49: 43769
...

Sheet Hoja 6

Sheet Lista de receptores
B3: Receptor A
B4: Nº | C4: Nombre | D4: Apellido | E4: Estatus
B5: 1A | C5: {=IFNA(VLOOKUP(B5,{'DATA DE CONTROLES Y LLAVES'!I$6:I1000,'DATA DE CONTROLES Y LLAVES'!F$6:F1000},2,FALSE),"")} -> DANIEL | D5: {=IFNA(VLOOKUP(B5,{'DATA DE CONTROLES Y LLAVES'!I$6:I1000,'DATA DE CONTROLES Y LLAVES'!G$6:G1000},2,FALSE),"")} -> FERNÁNDEZ | E5: ACTIVO
B6: 2A | C6: {=IFNA(VLOOKUP(B6,{'DATA DE CONTROLES Y LLAVES'!I$6:I1000,'DATA DE CONTROLES Y LLAVES'!F$6:F1000},2,FALSE),"")} | D6: {=IFNA(VLOOKUP(B6,{'DATA DE CONTROLES Y LLAVES'!I$6:I1000,'DATA DE CONTROLES Y LLAVES'!G$6:G1000},2,FALSE),"")} | E6: BLOQUEADO
B7: 3a | C7: {=IFNA(VLOOKUP(B7,{'DATA DE CONTROLES Y LLAVES'!I$6:I1000,'DATA DE CONTROLES Y LLAVES'!F$6:F1000},2,FALSE),"")} -> JOSEFINA | D7: {=IFNA(VLOOKUP(B7,{'DATA DE CONTROLES Y LLAVES'!I$6:I1000,'DATA DE CONTROLES Y LLAVES'!G$6:G1000},2,FALSE),"")} -> FERNÁNDEZ | E7: ACTIVO
B8: 4a | C8: {=IFNA(VLOOKUP(B8,{'DATA DE CONTROLES Y LLAVES'!I$6:I1000,'DATA DE CONTROLES Y LLAVES'!F$6:F1000},2,FALSE),"")} -> HAIDEÉ | D8: {=IFNA(VLOOKUP(B8,{'DATA DE CONTROLES Y LLAVES'!I$6:I1000,'DATA DE CONTROLES Y LLAVES'!G$6:G1000},2,FALSE),"")} -> FALCÓN | E8: ACTIVO
B9: 5a | C9: {=IFNA(VLOOKUP(B9,{'DATA DE CONTROLES Y LLAVES'!I$6:I1000,'DATA DE CONTROLES Y LLAVES'!F$6:F1000},2,FALSE),"")} -> JOSÉ | D9: {=IFNA(VLOOKUP(B9,{'DATA DE CONTROLES Y LLAVES'!I$6:I1000,'DATA DE CONTROLES Y LLAVES'!G$6:G1000},2,FALSE),"")} -> ACOSTA | E9: ACTIVO
B10: 6a | C10: {=IFNA(VLOOKUP(B10,{'DATA DE CONTROLES Y LLAVES'!I$6:I1000,'DATA DE CONTROLES Y LLAVES'!F$6:F1000},2,FALSE),"")} -> VICTOR | D10: {=IFNA(VLOOKUP(B10,{'DATA DE CONTROLES Y LLAVES'!I$6:I1000,'DATA DE CONTROLES Y LLAVES'!G$6:G1000},2,FALSE),"")} -> VIEIRA | E10: BLOQUEADO
B11: 7a | C11: {=IFNA(VLOOKUP(B11,{'DATA DE CONTROLES Y LLAVES'!I$6:I1000,'DATA DE CONTROLES Y LLAVES'!F$6:F1000},2,FALSE),"")} -> DENISE | D11: {=IFNA(VLOOKUP(B11,{'DATA DE CONTROLES Y LLAVES'!I$6:I1000,'DATA DE CONTROLES Y LLAVES'!G$6:G1000},2,FALSE),"")} -> ISTURIZ | E11: BLOQUEADO
B12: 8a | C12: {=IFNA(VLOOKUP(B12,{'DATA DE CONTROLES Y LLAVES'!I$6:I1000,'DATA DE CONTROLES Y LLAVES'!F$6:F1000},2,FALSE),"")} | D12: {=IFNA(VLOOKUP(B12,{'DATA DE CONTROLES Y LLAVES'!I$6:I1000,'DATA DE CONTROLES Y LLAVES'!G$6:G1000},2,FALSE),"")} | E12: ACTIVO
B13: 9a | C13: {=IFNA(VLOOKUP(B13,{'DATA DE CONTROLES Y LLAVES'!I$6:I1000,'DATA DE CONTROLES Y LLAVES'!F$6:F1000},2,FALSE),"")} | D13: {=IFNA(VLOOKUP(B13,{'DATA DE CONTROLES Y LLAVES'!I$6:I1000,'DATA DE CONTROLES Y LLAVES'!G$6:G1000},2,FALSE),"")} | E13: ACTIVO
B14: 10a | C14: {=IFNA(VLOOKUP(B14,{'DATA DE CONTROLES Y LLAVES'!I$6:I1000,'DATA DE CONTROLES Y LLAVES'!F$6:F1000},2,FALSE),"")} -> YELITZA | D14: {=IFNA(VLOOKUP(B14,{'DATA DE CONTROLES Y LLAVES'!I$6:I1000,'DATA DE CONTROLES Y LLAVES'!G$6:G1000},2,FALSE),"")} -> BIANCO | E14: ACTIVO
B15: 11a | C15: {=IFNA(VLOOKUP(B15,{'DATA DE CONTROLES Y LLAVES'!I$6:I1000,'DATA DE CONTROLES Y LLAVES'!F$6:F1000},2,FALSE),"")} -> LUISA | D15: {=IFNA(VLOOKUP(B15,{'DATA DE CONTROLES Y LLAVES'!I$6:I1000,'DATA DE CONTROLES Y LLAVES'!G$6:G1000},2,FALSE),"")} -> GARCÍA | E15: ACTIVO
B16: 12a | C16: {=IFNA(VLOOKUP(B16,{'DATA DE CONTROLES Y LLAVES'!I$6:I1000,'DATA DE CONTROLES Y LLAVES'!F$6:F1000},2,FALSE),"")} -> TAIZ | D16: {=IFNA(VLOOKUP(B16,{'DATA DE CONTROLES Y LLAVES'!I$6:I1000,'DATA DE CONTROLES Y LLAVES'!G$6:G1000},2,FALSE),"")} -> CONTRERAS | E16: ACTIVO
B17: 13a | C17: {=IFNA(VLOOKUP(B17,{'DATA DE CONTROLES Y LLAVES'!I$6:I1000,'DATA DE CONTROLES Y LLAVES'!F$6:F1000},2,FALSE),"")} -> DORIS | D17: {=IFNA(VLOOKUP(B17,{'DATA DE CONTROLES Y LLAVES'!I$6:I1000,'DATA DE CONTROLES Y LLAVES'!G$6:G1000},2,FALSE),"")} -> SANCHEZ | E17: BLOQUEADO
B18: 14a | C18: {=IFNA(VLOOKUP(B18,{'DATA DE CONTROLES Y LLAVES'!I$6:I1000,'DATA DE CONTROLES Y LLAVES'!F$6:F1000},2,FALSE),"")} | D18: {=IFNA(VLOOKUP(B18,{'DATA DE CONTROLES Y LLAVES'!I$6:I1000,'DATA DE CONTROLES Y LLAVES'!G$6:G1000},2,FALSE),"")} | E18: BLOQUEADO
B19: 15a | C19: {=IFNA(VLOOKUP(B19,{'DATA DE CONTROLES Y LLAVES'!I$6:I1000,'DATA DE CONTROLES Y LLAVES'!F$6:F1000},2,FALSE),"")} -> YADITZA | D19: {=IFNA(VLOOKUP(B19,{'DATA DE CONTROLES Y LLAVES'!I$6:I1000,'DATA DE CONTROLES Y LLAVES'!G$6:G1000},2,FALSE),"")} -> IRRAUSQUIN | E19: ACTIVO
B20: 16a | C20: {=IFNA(VLOOKUP(B20,{'DATA DE CONTROLES Y LLAVES'!I$6:I1000,'DATA DE CONTROLES Y LLAVES'!F$6:F1000},2,FALSE),"")} -> GLEISYS | D20: {=IFNA(VLOOKUP(B20,{'DATA DE CONTROLES Y LLAVES'!I$6:I1000,'DATA DE CONTROLES Y LLAVES'!G$6:G1000},2,FALSE),"")} -> CHAVEZ | E20: ACTIVO
B21: 17a | C21: {=IFNA(VLOOKUP(B21,{'DATA DE CONTROLES Y LLAVES'!I$6:I1000,'DATA DE CONTROLES Y LLAVES'!F$6:F1000},2,FALSE),"")} -> VICTOR | D21: {=IFNA(VLOOKUP(B21,{'DATA DE CONTROLES Y LLAVES'!I$6:I1000,'DATA DE CONTROLES Y LLAVES'!G$6:G1000},2,FALSE),"")} -> VERAMENDI | E21: ACTIVO
B22: 18a | C22: {=IFNA(VLOOKUP(B22,{'DATA DE CONTROLES Y LLAVES'!I$6:I1000,'DATA DE CONTROLES Y LLAVES'!F$6:F1000},2,FALSE),"")} -> VALENTINA | D22: {=IFNA(VLOOKUP(B22,{'DATA DE CONTROLES Y LLAVES'!I$6:I1000,'DATA DE CONTROLES Y LLAVES'!G$6:G1000},2,FALSE),"")} -> ESPINOZA | E22: ACTIVO
B23: 19a | C23: {=IFNA(VLOOKUP(B23,{'DATA DE CONTROLES Y LLAVES'!I$6:I1000,'DATA DE CONTROLES Y LLAVES'!F$6:F1000},2,FALSE),"")} -> KEIZLER | D23: {=IFNA(VLOOKUP(B23,{'DATA DE CONTROLES Y LLAVES'!I$6:I1000,'DATA DE CONTROLES Y LLAVES'!G$6:G1000},2,FALSE),"")} -> URBINA | E23: ACTIVO
B24: 20a | C24: {=IFNA(VLOOKUP(B24,{'DATA DE CONTROLES Y LLAVES'!I$6:I1000,'DATA DE CONTROLES Y LLAVES'!F$6:F1000},2,FALSE),"")} -> VICTOR | D24: {=IFNA(VLOOKUP(B24,{'DATA DE CONTROLES Y LLAVES'!I$6:I1000,'DATA DE CONTROLES Y LLAVES'!G$6:G1000},2,FALSE),"")} -> PEREZ | E24: ACTIVO
B25: 21a | C25: {=IFNA(VLOOKUP(B25,{'DATA DE CONTROLES Y LLAVES'!I$6:I1000,'DATA DE CONTROLES Y LLAVES'!F$6:F1000},2,FALSE),"")} -> JEIMI | D25: {=IFNA(VLOOKUP(B25,{'DATA DE CONTROLES Y LLAVES'!I$6:I1000,'DATA DE CONTROLES Y LLAVES'!G$6:G1000},2,FALSE),"")} -> DIAZ | E25: ACTIVO
B26: 22a | C26: {=IFNA(VLOOKUP(B26,{'DATA DE CONTROLES Y LLAVES'!I$6:I1000,'DATA DE CONTROLES Y LLAVES'!F$6:F1000},2,FALSE),"")} -> JOSÉ | D26: {=IFNA(VLOOKUP(B26,{'DATA DE CONTROLES Y LLAVES'!I$6:I1000,'DATA DE CONTROLES Y LLAVES'!G$6:G1000},2,FALSE),"")} -> VÁSQUEZ | E26: ACTIVO
B27: 23a | C27: {=IFNA(VLOOKUP(B27,{'DATA DE CONTROLES Y LLAVES'!I$6:I1000,'DATA DE CONTROLES Y LLAVES'!F$6:F1000},2,FALSE),"")} -> MARUJA | D27: {=IFNA(VLOOKUP(B27,{'DATA DE CONTROLES Y LLAVES'!I$6:I1000,'DATA DE CONTROLES Y LLAVES'!G$6:G1000},2,FALSE),"")} -> MARRERO | E27: BLOQUEADO
B28: 24a | C28: {=IFNA(VLOOKUP(B28,{'DATA DE CONTROLES Y LLAVES'!I$6:I1000,'DATA DE CONTROLES Y LLAVES'!F$6:F1000},2,FALSE),"")} -> RAMSES | D28: {=IFNA(VLOOKUP(B28,{'DATA DE CONTROLES Y LLAVES'!I$6:I1000,'DATA DE CONTROLES Y LLAVES'!G$6:G1000},2,FALSE),"")} -> ROJAS | E28: BLOQUEADO
B29: 25a | C29: {=IFNA(VLOOKUP(B29,{'DATA DE CONTROLES Y LLAVES'!I$6:I1000,'DATA DE CONTROLES Y LLAVES'!F$6:F1000},2,FALSE),"")} -> JOEL | D29: {=IFNA(VLOOKUP(B29,{'DATA DE CONTROLES Y LLAVES'!I$6:I1000,'DATA DE CONTROLES Y LLAVES'!G$6:G1000},2,FALSE),"")} -> MARTINEZ | E29: BLOQUEADO
B30: 26a | C30: {=IFNA(VLOOKUP(B30,{'DATA DE CONTROLES Y LLAVES'!I$6:I1000,'DATA DE CONTROLES Y LLAVES'!F$6:F1000},2,FALSE),"")} -> FERNANDO | D30: {=IFNA(VLOOKUP(B30,{'DATA DE CONTROLES Y LLAVES'!I$6:I1000,'DATA DE CONTROLES Y LLAVES'!G$6:G1000},2,FALSE),"")} -> DOS REY | E30: ACTIVO
B31: 27a | C31: {=IFNA(VLOOKUP(B31,{'DATA DE CONTROLES Y LLAVES'!I$6:I1000,'DATA DE CONTROLES Y LLAVES'!F$6:F1000},2,FALSE),"")} -> MAMERTO | D31: {=IFNA(VLOOKUP(B31,{'DATA DE CONTROLES Y LLAVES'!I$6:I1000,'DATA DE CONTROLES Y LLAVES'!G$6:G1000},2,FALSE),"")} -> IRRAUSQUIN | E31: SUSPENDIDO
B32: 28a | C32: {=IFNA(VLOOKUP(B32,{'DATA DE CONTROLES Y LLAVES'!I$6:I1000,'DATA DE CONTROLES Y LLAVES'!F$6:F1000},2,FALSE),"")} -> EMMA | D32: {=IFNA(VLOOKUP(B32,{'DATA DE CONTROLES Y LLAVES'!I$6:I1000,'DATA DE CONTROLES Y LLAVES'!G$6:G1000},2,FALSE),"")} -> HERNÁNDEZ | E32: ACTIVO
B33: 29a | C33: {=IFNA(VLOOKUP(B33,{'DATA DE CONTROLES Y LLAVES'!I$6:I1000,'DATA DE CONTROLES Y LLAVES'!F$6:F1000},2,FALSE),"")} -> HAILER | D33: {=IFNA(VLOOKUP(B33,{'DATA DE CONTROLES Y LLAVES'!I$6:I1000,'DATA DE CONTROLES Y LLAVES'!G$6:G1000},2,FALSE),"")} -> QUERALES | E33: BLOQUEADO
B34: 30a | C34: {=IFNA(VLOOKUP(B34,{'DATA DE CONTROLES Y LLAVES'!I$6:I1000,'DATA DE CONTROLES Y LLAVES'!F$6:F1000},2,FALSE),"")} -> GLORIA | D34: {=IFNA(VLOOKUP(B34,{'DATA DE CONTROLES Y LLAVES'!I$6:I1000,'DATA DE CONTROLES Y LLAVES'!G$6:G1000},2,FALSE),"")} -> DELGADO | E34: ACTIVO
B35: 31a | C35: {=IFNA(VLOOKUP(B35,{'DATA DE CONTROLES Y LLAVES'!I$6:I1000,'DATA DE CONTROLES Y LLAVES'!F$6:F1000},2,FALSE),"")} -> DANIEL | D35: {=IFNA(VLOOKUP(B35,{'DATA DE CONTROLES Y LLAVES'!I$6:I1000,'DATA DE CONTROLES Y LLAVES'!G$6:G1000},2,FALSE),"")} -> DA COSTA | E35: ACTIVO
B36: 32a | C36: {=IFNA(VLOOKUP(B36,{'DATA DE CONTROLES Y LLAVES'!I$6:I1000,'DATA DE CONTROLES Y LLAVES'!F$6:F1000},2,FALSE),"")} -> HUGO | D36: {=IFNA(VLOOKUP(B36,{'DATA DE CONTROLES Y LLAVES'!I$6:I1000,'DATA DE CONTROLES Y LLAVES'!G$6:G1000},2,FALSE),"")} -> URUBURU | E36: ACTIVO
B37: 33a | C37: {=IFNA(VLOOKUP(B37,{'DATA DE CONTROLES Y LLAVES'!I$6:I1000,'DATA DE CONTROLES Y LLAVES'!F$6:F1000},2,FALSE),"")} -> JENIFER | D37: {=IFNA(VLOOKUP(B37,{'DATA DE CONTROLES Y LLAVES'!I$6:I1000,'DATA DE CONTROLES Y LLAVES'!G$6:G1000},2,FALSE),"")} -> URUBURU | E37: ACTIVO
B38: 34a | C38: {=IFNA(VLOOKUP(B38,{'DATA DE CONTROLES Y LLAVES'!I$6:I1000,'DATA DE CONTROLES Y LLAVES'!F$6:F1000},2,FALSE),"")} | D38: {=IFNA(VLOOKUP(B38,{'DATA DE CONTROLES Y LLAVES'!I$6:I1000,'DATA DE CONTROLES Y LLAVES'!G$6:G1000},2,FALSE),"")} | E38: ACTIVO
B39: 35a | C39: {=IFNA(VLOOKUP(B39,{'DATA DE CONTROLES Y LLAVES'!I$6:I1000,'DATA DE CONTROLES Y LLAVES'!F$6:F1000},2,FALSE),"")} -> ARTURO | D39: {=IFNA(VLOOKUP(B39,{'DATA DE CONTROLES Y LLAVES'!I$6:I1000,'DATA DE CONTROLES Y LLAVES'!G$6:G1000},2,FALSE),"")} -> BORRERO | E39: ACTIVO
B40: 36a | C40: {=IFNA(VLOOKUP(B40,{'DATA DE CONTROLES Y LLAVES'!I$6:I1000,'DATA DE CONTROLES Y LLAVES'!F$6:F1000},2,FALSE),"")} -> DULCE | D40: {=IFNA(VLOOKUP(B40,{'DATA DE CONTROLES Y LLAVES'!I$6:I1000,'DATA DE CONTROLES Y LLAVES'!G$6:G1000},2,FALSE),"")} -> MUÑOZ | E40: BLOQUEADO
B41: 37a | C41: {=IFNA(VLOOKUP(B41,{'DATA DE CONTROLES Y LLAVES'!I$6:I1000,'DATA DE CONTROLES Y LLAVES'!F$6:F1000},2,FALSE),"")} -> LORENA | D41: {=IFNA(VLOOKUP(B41,{'DATA DE CONTROLES Y LLAVES'!I$6:I1000,'DATA DE CONTROLES Y LLAVES'!G$6:G1000},2,FALSE),"")} -> GARCIA | E41: BLOQUEADO
B42: 38a | C42: {=IFNA(VLOOKUP(B42,{'DATA DE CONTROLES Y LLAVES'!I$6:I1000,'DATA DE CONTROLES Y LLAVES'!F$6:F1000},2,FALSE),"")} -> EDGARDO | D42: {=IFNA(VLOOKUP(B42,{'DATA DE CONTROLES Y LLAVES'!I$6:I1000,'DATA DE CONTROLES Y LLAVES'!G$6:G1000},2,FALSE),"")} -> IBARRA | E42: ACTIVO
...
